Watching for file changes with StatReloader
Performing system checks...

System check identified no issues (0 silenced).

You have 15 unapplied migration(s). Your project may not work properly until you apply the migrations for app(s): api.
Run 'python manage.py migrate' to apply them.
July 09, 2024 - 11:08:48
Django version 3.2.25, using settings 'transcendence.settings'
Starting development server at http://0.0.0.0:8000/
Quit the server with CONTROL-C.
[09/Jul/2024 11:10:54] "GET /fr/login/ HTTP/1.1" 200 8709
[09/Jul/2024 11:10:54] "GET /fr/login/ HTTP/1.1" 200 8709
[09/Jul/2024 11:10:54] "GET /fr/login/ HTTP/1.1" 200 8709
[09/Jul/2024 11:10:55] "GET /fr/login/ HTTP/1.1" 200 8709
Internal Server Error: /api/@me/
Traceback (most recent call last):
  File "/root/.local/share/virtualenvs/app-lp47FrbD/lib/python3.11/site-packages/django/db/backends/utils.py", line 84, in _execute
    return self.cursor.execute(sql, params)
           ^^^^^^^^^^^^^^^^^^^^^^^^^^^^^^^^
  File "/root/.local/share/virtualenvs/app-lp47FrbD/lib/python3.11/site-packages/django/db/backends/mysql/base.py", line 73, in execute
    return self.cursor.execute(query, args)
           ^^^^^^^^^^^^^^^^^^^^^^^^^^^^^^^^
  File "/root/.local/share/virtualenvs/app-lp47FrbD/lib/python3.11/site-packages/pymysql/cursors.py", line 148, in execute
    result = self._query(query)
             ^^^^^^^^^^^^^^^^^^
  File "/root/.local/share/virtualenvs/app-lp47FrbD/lib/python3.11/site-packages/pymysql/cursors.py", line 310, in _query
    conn.query(q)
  File "/root/.local/share/virtualenvs/app-lp47FrbD/lib/python3.11/site-packages/pymysql/connections.py", line 548, in query
    self._affected_rows = self._read_query_result(unbuffered=unbuffered)
                          ^^^^^^^^^^^^^^^^^^^^^^^^^^^^^^^^^^^^^^^^^^^^^^
  File "/root/.local/share/virtualenvs/app-lp47FrbD/lib/python3.11/site-packages/pymysql/connections.py", line 775, in _read_query_result
    result.read()
  File "/root/.local/share/virtualenvs/app-lp47FrbD/lib/python3.11/site-packages/pymysql/connections.py", line 1156, in read
    first_packet = self.connection._read_packet()
                   ^^^^^^^^^^^^^^^^^^^^^^^^^^^^^^
  File "/root/.local/share/virtualenvs/app-lp47FrbD/lib/python3.11/site-packages/pymysql/connections.py", line 725, in _read_packet
    packet.raise_for_error()
  File "/root/.local/share/virtualenvs/app-lp47FrbD/lib/python3.11/site-packages/pymysql/protocol.py", line 221, in raise_for_error
    err.raise_mysql_exception(self._data)
  File "/root/.local/share/virtualenvs/app-lp47FrbD/lib/python3.11/site-packages/pymysql/err.py", line 143, in raise_mysql_exception
    raise errorclass(errno, errval)
pymysql.err.OperationalError: (1054, "Unknown column 'api_player.password' in 'field list'")

The above exception was the direct cause of the following exception:

Traceback (most recent call last):
  File "/root/.local/share/virtualenvs/app-lp47FrbD/lib/python3.11/site-packages/django/core/handlers/exception.py", line 47, in inner
    response = get_response(request)
               ^^^^^^^^^^^^^^^^^^^^^
  File "/root/.local/share/virtualenvs/app-lp47FrbD/lib/python3.11/site-packages/django/core/handlers/base.py", line 181, in _get_response
    response = wrapped_callback(request, *callback_args, **callback_kwargs)
               ^^^^^^^^^^^^^^^^^^^^^^^^^^^^^^^^^^^^^^^^^^^^^^^^^^^^^^^^^^^^
  File "/root/.local/share/virtualenvs/app-lp47FrbD/lib/python3.11/site-packages/django/views/decorators/csrf.py", line 54, in wrapped_view
    return view_func(*args, **kwargs)
           ^^^^^^^^^^^^^^^^^^^^^^^^^^
  File "/root/.local/share/virtualenvs/app-lp47FrbD/lib/python3.11/site-packages/django/views/generic/base.py", line 70, in view
    return self.dispatch(request, *args, **kwargs)
           ^^^^^^^^^^^^^^^^^^^^^^^^^^^^^^^^^^^^^^^
  File "/root/.local/share/virtualenvs/app-lp47FrbD/lib/python3.11/site-packages/rest_framework/views.py", line 509, in dispatch
    response = self.handle_exception(exc)
               ^^^^^^^^^^^^^^^^^^^^^^^^^^
  File "/root/.local/share/virtualenvs/app-lp47FrbD/lib/python3.11/site-packages/rest_framework/views.py", line 469, in handle_exception
    self.raise_uncaught_exception(exc)
  File "/root/.local/share/virtualenvs/app-lp47FrbD/lib/python3.11/site-packages/rest_framework/views.py", line 480, in raise_uncaught_exception
    raise exc
  File "/root/.local/share/virtualenvs/app-lp47FrbD/lib/python3.11/site-packages/rest_framework/views.py", line 506, in dispatch
    response = handler(request, *args, **kwargs)
               ^^^^^^^^^^^^^^^^^^^^^^^^^^^^^^^^^
  File "/root/.local/share/virtualenvs/app-lp47FrbD/lib/python3.11/site-packages/rest_framework/decorators.py", line 50, in handler
    return func(*args, **kwargs)
           ^^^^^^^^^^^^^^^^^^^^^
  File "/usr/src/app/api/views.py", line 27, in get_me
    player = Player.objects.get(username=user)
             ^^^^^^^^^^^^^^^^^^^^^^^^^^^^^^^^^
  File "/root/.local/share/virtualenvs/app-lp47FrbD/lib/python3.11/site-packages/django/db/models/manager.py", line 85, in manager_method
    return getattr(self.get_queryset(), name)(*args, **kwargs)
           ^^^^^^^^^^^^^^^^^^^^^^^^^^^^^^^^^^^^^^^^^^^^^^^^^^^
  File "/root/.local/share/virtualenvs/app-lp47FrbD/lib/python3.11/site-packages/django/db/models/query.py", line 431, in get
    num = len(clone)
          ^^^^^^^^^^
  File "/root/.local/share/virtualenvs/app-lp47FrbD/lib/python3.11/site-packages/django/db/models/query.py", line 262, in __len__
    self._fetch_all()
  File "/root/.local/share/virtualenvs/app-lp47FrbD/lib/python3.11/site-packages/django/db/models/query.py", line 1324, in _fetch_all
    self._result_cache = list(self._iterable_class(self))
                         ^^^^^^^^^^^^^^^^^^^^^^^^^^^^^^^^
  File "/root/.local/share/virtualenvs/app-lp47FrbD/lib/python3.11/site-packages/django/db/models/query.py", line 51, in __iter__
    results = compiler.execute_sql(chunked_fetch=self.chunked_fetch, chunk_size=self.chunk_size)
              ^^^^^^^^^^^^^^^^^^^^^^^^^^^^^^^^^^^^^^^^^^^^^^^^^^^^^^^^^^^^^^^^^^^^^^^^^^^^^^^^^^
  File "/root/.local/share/virtualenvs/app-lp47FrbD/lib/python3.11/site-packages/django/db/models/sql/compiler.py", line 1175, in execute_sql
    cursor.execute(sql, params)
  File "/root/.local/share/virtualenvs/app-lp47FrbD/lib/python3.11/site-packages/django/db/backends/utils.py", line 98, in execute
    return super().execute(sql, params)
           ^^^^^^^^^^^^^^^^^^^^^^^^^^^^
  File "/root/.local/share/virtualenvs/app-lp47FrbD/lib/python3.11/site-packages/django/db/backends/utils.py", line 66, in execute
    return self._execute_with_wrappers(sql, params, many=False, executor=self._execute)
           ^^^^^^^^^^^^^^^^^^^^^^^^^^^^^^^^^^^^^^^^^^^^^^^^^^^^^^^^^^^^^^^^^^^^^^^^^^^^
  File "/root/.local/share/virtualenvs/app-lp47FrbD/lib/python3.11/site-packages/django/db/backends/utils.py", line 75, in _execute_with_wrappers
    return executor(sql, params, many, context)
           ^^^^^^^^^^^^^^^^^^^^^^^^^^^^^^^^^^^^
  File "/root/.local/share/virtualenvs/app-lp47FrbD/lib/python3.11/site-packages/django/db/backends/utils.py", line 79, in _execute
    with self.db.wrap_database_errors:
  File "/root/.local/share/virtualenvs/app-lp47FrbD/lib/python3.11/site-packages/django/db/utils.py", line 90, in __exit__
    raise dj_exc_value.with_traceback(traceback) from exc_value
  File "/root/.local/share/virtualenvs/app-lp47FrbD/lib/python3.11/site-packages/django/db/backends/utils.py", line 84, in _execute
    return self.cursor.execute(sql, params)
           ^^^^^^^^^^^^^^^^^^^^^^^^^^^^^^^^
  File "/root/.local/share/virtualenvs/app-lp47FrbD/lib/python3.11/site-packages/django/db/backends/mysql/base.py", line 73, in execute
    return self.cursor.execute(query, args)
           ^^^^^^^^^^^^^^^^^^^^^^^^^^^^^^^^
  File "/root/.local/share/virtualenvs/app-lp47FrbD/lib/python3.11/site-packages/pymysql/cursors.py", line 148, in execute
    result = self._query(query)
             ^^^^^^^^^^^^^^^^^^
  File "/root/.local/share/virtualenvs/app-lp47FrbD/lib/python3.11/site-packages/pymysql/cursors.py", line 310, in _query
    conn.query(q)
  File "/root/.local/share/virtualenvs/app-lp47FrbD/lib/python3.11/site-packages/pymysql/connections.py", line 548, in query
    self._affected_rows = self._read_query_result(unbuffered=unbuffered)
                          ^^^^^^^^^^^^^^^^^^^^^^^^^^^^^^^^^^^^^^^^^^^^^^
  File "/root/.local/share/virtualenvs/app-lp47FrbD/lib/python3.11/site-packages/pymysql/connections.py", line 775, in _read_query_result
    result.read()
  File "/root/.local/share/virtualenvs/app-lp47FrbD/lib/python3.11/site-packages/pymysql/connections.py", line 1156, in read
    first_packet = self.connection._read_packet()
                   ^^^^^^^^^^^^^^^^^^^^^^^^^^^^^^
  File "/root/.local/share/virtualenvs/app-lp47FrbD/lib/python3.11/site-packages/pymysql/connections.py", line 725, in _read_packet
    packet.raise_for_error()
  File "/root/.local/share/virtualenvs/app-lp47FrbD/lib/python3.11/site-packages/pymysql/protocol.py", line 221, in raise_for_error
    err.raise_mysql_exception(self._data)
  File "/root/.local/share/virtualenvs/app-lp47FrbD/lib/python3.11/site-packages/pymysql/err.py", line 143, in raise_mysql_exception
    raise errorclass(errno, errval)
django.db.utils.OperationalError: (1054, "Unknown column 'api_player.password' in 'field list'")
[09/Jul/2024 11:10:55] "GET /api/@me/ HTTP/1.1" 500 227033
Internal Server Error: /api/login_player/
Traceback (most recent call last):
  File "/root/.local/share/virtualenvs/app-lp47FrbD/lib/python3.11/site-packages/django/db/backends/utils.py", line 84, in _execute
    return self.cursor.execute(sql, params)
           ^^^^^^^^^^^^^^^^^^^^^^^^^^^^^^^^
  File "/root/.local/share/virtualenvs/app-lp47FrbD/lib/python3.11/site-packages/django/db/backends/mysql/base.py", line 73, in execute
    return self.cursor.execute(query, args)
           ^^^^^^^^^^^^^^^^^^^^^^^^^^^^^^^^
  File "/root/.local/share/virtualenvs/app-lp47FrbD/lib/python3.11/site-packages/pymysql/cursors.py", line 148, in execute
    result = self._query(query)
             ^^^^^^^^^^^^^^^^^^
  File "/root/.local/share/virtualenvs/app-lp47FrbD/lib/python3.11/site-packages/pymysql/cursors.py", line 310, in _query
    conn.query(q)
  File "/root/.local/share/virtualenvs/app-lp47FrbD/lib/python3.11/site-packages/pymysql/connections.py", line 548, in query
    self._affected_rows = self._read_query_result(unbuffered=unbuffered)
                          ^^^^^^^^^^^^^^^^^^^^^^^^^^^^^^^^^^^^^^^^^^^^^^
  File "/root/.local/share/virtualenvs/app-lp47FrbD/lib/python3.11/site-packages/pymysql/connections.py", line 775, in _read_query_result
    result.read()
  File "/root/.local/share/virtualenvs/app-lp47FrbD/lib/python3.11/site-packages/pymysql/connections.py", line 1156, in read
    first_packet = self.connection._read_packet()
                   ^^^^^^^^^^^^^^^^^^^^^^^^^^^^^^
  File "/root/.local/share/virtualenvs/app-lp47FrbD/lib/python3.11/site-packages/pymysql/connections.py", line 725, in _read_packet
    packet.raise_for_error()
  File "/root/.local/share/virtualenvs/app-lp47FrbD/lib/python3.11/site-packages/pymysql/protocol.py", line 221, in raise_for_error
    err.raise_mysql_exception(self._data)
  File "/root/.local/share/virtualenvs/app-lp47FrbD/lib/python3.11/site-packages/pymysql/err.py", line 143, in raise_mysql_exception
    raise errorclass(errno, errval)
pymysql.err.OperationalError: (1054, "Unknown column 'api_player.password' in 'field list'")

The above exception was the direct cause of the following exception:

Traceback (most recent call last):
  File "/root/.local/share/virtualenvs/app-lp47FrbD/lib/python3.11/site-packages/django/core/handlers/exception.py", line 47, in inner
    response = get_response(request)
               ^^^^^^^^^^^^^^^^^^^^^
  File "/root/.local/share/virtualenvs/app-lp47FrbD/lib/python3.11/site-packages/django/core/handlers/base.py", line 181, in _get_response
    response = wrapped_callback(request, *callback_args, **callback_kwargs)
               ^^^^^^^^^^^^^^^^^^^^^^^^^^^^^^^^^^^^^^^^^^^^^^^^^^^^^^^^^^^^
  File "/root/.local/share/virtualenvs/app-lp47FrbD/lib/python3.11/site-packages/django/views/decorators/csrf.py", line 54, in wrapped_view
    return view_func(*args, **kwargs)
           ^^^^^^^^^^^^^^^^^^^^^^^^^^
  File "/root/.local/share/virtualenvs/app-lp47FrbD/lib/python3.11/site-packages/django/views/generic/base.py", line 70, in view
    return self.dispatch(request, *args, **kwargs)
           ^^^^^^^^^^^^^^^^^^^^^^^^^^^^^^^^^^^^^^^
  File "/root/.local/share/virtualenvs/app-lp47FrbD/lib/python3.11/site-packages/rest_framework/views.py", line 509, in dispatch
    response = self.handle_exception(exc)
               ^^^^^^^^^^^^^^^^^^^^^^^^^^
  File "/root/.local/share/virtualenvs/app-lp47FrbD/lib/python3.11/site-packages/rest_framework/views.py", line 469, in handle_exception
    self.raise_uncaught_exception(exc)
  File "/root/.local/share/virtualenvs/app-lp47FrbD/lib/python3.11/site-packages/rest_framework/views.py", line 480, in raise_uncaught_exception
    raise exc
  File "/root/.local/share/virtualenvs/app-lp47FrbD/lib/python3.11/site-packages/rest_framework/views.py", line 506, in dispatch
    response = handler(request, *args, **kwargs)
               ^^^^^^^^^^^^^^^^^^^^^^^^^^^^^^^^^
  File "/root/.local/share/virtualenvs/app-lp47FrbD/lib/python3.11/site-packages/rest_framework/decorators.py", line 50, in handler
    return func(*args, **kwargs)
           ^^^^^^^^^^^^^^^^^^^^^
  File "/usr/src/app/api/views_users.py", line 26, in login_player
    player = Player.objects.get(mail=mail)
             ^^^^^^^^^^^^^^^^^^^^^^^^^^^^^
  File "/root/.local/share/virtualenvs/app-lp47FrbD/lib/python3.11/site-packages/django/db/models/manager.py", line 85, in manager_method
    return getattr(self.get_queryset(), name)(*args, **kwargs)
           ^^^^^^^^^^^^^^^^^^^^^^^^^^^^^^^^^^^^^^^^^^^^^^^^^^^
  File "/root/.local/share/virtualenvs/app-lp47FrbD/lib/python3.11/site-packages/django/db/models/query.py", line 431, in get
    num = len(clone)
          ^^^^^^^^^^
  File "/root/.local/share/virtualenvs/app-lp47FrbD/lib/python3.11/site-packages/django/db/models/query.py", line 262, in __len__
    self._fetch_all()
  File "/root/.local/share/virtualenvs/app-lp47FrbD/lib/python3.11/site-packages/django/db/models/query.py", line 1324, in _fetch_all
    self._result_cache = list(self._iterable_class(self))
                         ^^^^^^^^^^^^^^^^^^^^^^^^^^^^^^^^
  File "/root/.local/share/virtualenvs/app-lp47FrbD/lib/python3.11/site-packages/django/db/models/query.py", line 51, in __iter__
    results = compiler.execute_sql(chunked_fetch=self.chunked_fetch, chunk_size=self.chunk_size)
              ^^^^^^^^^^^^^^^^^^^^^^^^^^^^^^^^^^^^^^^^^^^^^^^^^^^^^^^^^^^^^^^^^^^^^^^^^^^^^^^^^^
  File "/root/.local/share/virtualenvs/app-lp47FrbD/lib/python3.11/site-packages/django/db/models/sql/compiler.py", line 1175, in execute_sql
    cursor.execute(sql, params)
  File "/root/.local/share/virtualenvs/app-lp47FrbD/lib/python3.11/site-packages/django/db/backends/utils.py", line 98, in execute
    return super().execute(sql, params)
           ^^^^^^^^^^^^^^^^^^^^^^^^^^^^
  File "/root/.local/share/virtualenvs/app-lp47FrbD/lib/python3.11/site-packages/django/db/backends/utils.py", line 66, in execute
    return self._execute_with_wrappers(sql, params, many=False, executor=self._execute)
           ^^^^^^^^^^^^^^^^^^^^^^^^^^^^^^^^^^^^^^^^^^^^^^^^^^^^^^^^^^^^^^^^^^^^^^^^^^^^
  File "/root/.local/share/virtualenvs/app-lp47FrbD/lib/python3.11/site-packages/django/db/backends/utils.py", line 75, in _execute_with_wrappers
    return executor(sql, params, many, context)
           ^^^^^^^^^^^^^^^^^^^^^^^^^^^^^^^^^^^^
  File "/root/.local/share/virtualenvs/app-lp47FrbD/lib/python3.11/site-packages/django/db/backends/utils.py", line 79, in _execute
    with self.db.wrap_database_errors:
  File "/root/.local/share/virtualenvs/app-lp47FrbD/lib/python3.11/site-packages/django/db/utils.py", line 90, in __exit__
    raise dj_exc_value.with_traceback(traceback) from exc_value
  File "/root/.local/share/virtualenvs/app-lp47FrbD/lib/python3.11/site-packages/django/db/backends/utils.py", line 84, in _execute
    return self.cursor.execute(sql, params)
           ^^^^^^^^^^^^^^^^^^^^^^^^^^^^^^^^
  File "/root/.local/share/virtualenvs/app-lp47FrbD/lib/python3.11/site-packages/django/db/backends/mysql/base.py", line 73, in execute
    return self.cursor.execute(query, args)
           ^^^^^^^^^^^^^^^^^^^^^^^^^^^^^^^^
  File "/root/.local/share/virtualenvs/app-lp47FrbD/lib/python3.11/site-packages/pymysql/cursors.py", line 148, in execute
    result = self._query(query)
             ^^^^^^^^^^^^^^^^^^
  File "/root/.local/share/virtualenvs/app-lp47FrbD/lib/python3.11/site-packages/pymysql/cursors.py", line 310, in _query
    conn.query(q)
  File "/root/.local/share/virtualenvs/app-lp47FrbD/lib/python3.11/site-packages/pymysql/connections.py", line 548, in query
    self._affected_rows = self._read_query_result(unbuffered=unbuffered)
                          ^^^^^^^^^^^^^^^^^^^^^^^^^^^^^^^^^^^^^^^^^^^^^^
  File "/root/.local/share/virtualenvs/app-lp47FrbD/lib/python3.11/site-packages/pymysql/connections.py", line 775, in _read_query_result
    result.read()
  File "/root/.local/share/virtualenvs/app-lp47FrbD/lib/python3.11/site-packages/pymysql/connections.py", line 1156, in read
    first_packet = self.connection._read_packet()
                   ^^^^^^^^^^^^^^^^^^^^^^^^^^^^^^
  File "/root/.local/share/virtualenvs/app-lp47FrbD/lib/python3.11/site-packages/pymysql/connections.py", line 725, in _read_packet
    packet.raise_for_error()
  File "/root/.local/share/virtualenvs/app-lp47FrbD/lib/python3.11/site-packages/pymysql/protocol.py", line 221, in raise_for_error
    err.raise_mysql_exception(self._data)
  File "/root/.local/share/virtualenvs/app-lp47FrbD/lib/python3.11/site-packages/pymysql/err.py", line 143, in raise_mysql_exception
    raise errorclass(errno, errval)
django.db.utils.OperationalError: (1054, "Unknown column 'api_player.password' in 'field list'")
[09/Jul/2024 11:11:05] "POST /api/login_player/ HTTP/1.1" 500 228568
